Workbook

Sheet fixed_generators
A1: scenario | B1: station_name | C1: parameter | D1: 2019 | E1: 2020 | F1: =E1+1 -> 2021 | G1: =F1+1 -> 2022 | H1: =G1+1 -> 2023 | I1: =H1+1 -> 2024 | J1: =I1+1 -> 2025 | K1: =J1+1 -> 2026 | L1: =K1+1 -> 2027 | M1: =L1+1 -> 2028 | ... AS1: =AR1+1 -> 2060
A2: ME_IRP23 | B2: variable_coal | C2: fuel_price (R/GJ) | J2: 37.741118 | K2: 41.652043 | L2: 46.571714 | M2: 49.303235 | N2: 52.352593 | O2: 55.610825 | P2: =O2 -> 55.610825 | Q2: =P2 -> 55.610825 | R2: =Q2 -> 55.610825 | S2: =R2 -> 55.610825 | T2: =S2 -> 55.610825 | U2: =T2 -> 55.610825 | V2: =U2 -> 55.610825 | W2: =V2 -> 55.610825 | ... AS2: =AR2 -> 55.610825
A3: =A2 -> ME_IRP23 | B3: variable_diesel | C3: fuel_price (R/GJ) | D3: 816 | E3: 816 | F3: 816 | G3: 816 | H3: 816 | I3: 816 | J3: 864.96 | K3: 864.96 | L3: 864.96 | M3: 864.96 | N3: 864.96 | O3: 864.96 | P3: 864.96 | Q3: 864.96 | R3: 864.96 | S3: 864.96 | T3: 864.96 | U3: 864.96 | V3: 864.96 | W3: 864.96 | X3: 864.96 | Y3: 864.96 | Z3: 864.96 | AA3: 864.96 | AB3: 864.96 | AC3: 864.96 | AD3: 864.96 | AE3: 864.96 | AF3: 864.96 | AG3: 864.96 | AH3: 864.96 | AI3: 864.96 | AJ3: =AI3 -> 864.96 | AK3: =AJ3 -> 864.96 | AL3: =AK3 -> 864.96 | AM3: =AL3 -> 864.96 | AN3: =AM3 -> 864.96 | AO3: =AN3 -> 864.96 | AP3: =AO3 -> 864.96 | AQ3: =AP3 -> 864.96 | ... AS3: =AR3 -> 864.96
A4: HIGH | B4: variable_coal | C4: fuel_price (R/GJ) | J4: 37.741118 | K4: 41.652043 | L4: 46.571714 | M4: 49.303235 | N4: 52.352593 | O4: 55.610825 | P4: =O4 -> 55.610825 | Q4: =P4 -> 55.610825 | R4: =Q4 -> 55.610825 | S4: =R4 -> 55.610825 | T4: =S4 -> 55.610825 | U4: =T4 -> 55.610825 | V4: =U4 -> 55.610825 | W4: =V4 -> 55.610825 | ... AS4: =AR4 -> 55.610825
A5: =A4 -> HIGH | B5: variable_diesel | C5: fuel_price (R/GJ) | D5: 816 | E5: 816 | F5: 816 | G5: 816 | H5: 816 | I5: 816 | J5: =extendable_generators!J26 -> 388.87 | K5: =extendable_generators!K26 -> 404.1 | L5: =extendable_generators!L26 -> 418.4 | M5: =extendable_generators!M26 -> 432.19 | N5: =extendable_generators!N26 -> 446.49 | O5: =extendable_generators!O26 -> 462.62 | P5: =extendable_generators!P26 -> 468.14 | Q5: =extendable_generators!Q26 -> 468.5 | ... AS5: =extendable_generators!AS26 -> 544
A6: =A5 -> HIGH | B6: low_group | C6: fuel_price (R/GJ) | J6: =0.74*J4 -> 27.928428 | K6: =0.74*K4 -> 30.822512 | L6: =0.74*L4 -> 34.463068 | M6: =0.74*M4 -> 36.484394 | N6: =0.74*N4 -> 38.740919 | O6: =0.74*O4 -> 41.15201 | P6: =0.74*P4 -> 41.15201 | Q6: =0.74*Q4 -> 41.15201 | ... AS6: =0.74*AS4 -> 41.15201
A7: =A8 -> HIGH | B7: med_group | C7: fuel_price (R/GJ) | J7: =1.06*J4 -> 40.005585 | K7: =1.06*K4 -> 44.151166 | L7: =1.06*L4 -> 49.366017 | M7: =1.06*M4 -> 52.261429 | N7: =1.06*N4 -> 55.493749 | O7: =1.06*O4 -> 58.947474 | P7: =1.06*P4 -> 58.947474 | Q7: =1.06*Q4 -> 58.947474 | ... AS7: =1.06*AS4 -> 58.947474
A8: =A6 -> HIGH | B8: high_group | C8: fuel_price (R/GJ) | J8: =1.28*J4 -> 48.308631 | K8: =1.28*K4 -> 53.314616 | L8: =1.28*L4 -> 59.611794 | M8: =1.28*M4 -> 63.10814 | N8: =1.28*N4 -> 67.011319 | O8: =1.28*O4 -> 71.181856 | P8: =1.28*P4 -> 71.181856 | Q8: =1.28*Q4 -> 71.181856 | ... AS8: =1.28*AS4 -> 71.181856
A9: BASE | B9: variable_coal | C9: fuel_price (R/GJ) | J9: 37.741118 | K9: 41.652043 | L9: 46.571714 | M9: 49.303235 | N9: 52.352593 | O9: 55.610825 | P9: =O9 -> 55.610825 | Q9: =P9 -> 55.610825 | R9: =Q9 -> 55.610825 | S9: =R9 -> 55.610825 | T9: =S9 -> 55.610825 | U9: =T9 -> 55.610825 | V9: =U9 -> 55.610825 | W9: =V9 -> 55.610825 | ... AS9: =AR9 -> 55.610825
A10: =A9 -> BASE | B10: variable_diesel | C10: fuel_price (R/GJ) | D10: 816 | E10: 816 | F10: 816 | G10: 816 | H10: 816 | I10: 816 | J10: =extendable_generators!J38 -> 388.87 | K10: =extendable_generators!K38 -> 388.6 | L10: =extendable_generators!L38 -> 386.77 | M10: =extendable_generators!M38 -> 384.37 | N10: =extendable_generators!N38 -> 382.13 | O10: =extendable_generators!O38 -> 381.53 | P10: =extendable_generators!P38 -> 383.6 | Q10: =extendable_generators!Q38 -> 381.66 | ... AS10: =extendable_generators!AS38 -> 424
A11: =A10 -> BASE | B11: low_group | C11: fuel_price (R/GJ) | J11: =0.74*J9 -> 27.928428 | K11: =0.74*K9 -> 30.822512 | L11: =0.74*L9 -> 34.463068 | M11: =0.74*M9 -> 36.484394 | N11: =0.74*N9 -> 38.740919 | O11: =0.74*O9 -> 41.15201 | P11: =0.74*P9 -> 41.15201 | Q11: =0.74*Q9 -> 41.15201 | ... AS11: =0.74*AS9 -> 41.15201
A12: =A11 -> BASE | B12: med_group | C12: fuel_price (R/GJ) | J12: =1.06*J9 -> 40.005585 | K12: =1.06*K9 -> 44.151166 | L12: =1.06*L9 -> 49.366017 | M12: =1.06*M9 -> 52.261429 | N12: =1.06*N9 -> 55.493749 | O12: =1.06*O9 -> 58.947474 | P12: =1.06*P9 -> 58.947474 | Q12: =1.06*Q9 -> 58.947474 | ... AS12: =1.06*AS9 -> 58.947474
A13: =A12 -> BASE | B13: high_group | C13: fuel_price (R/GJ) | J13: =1.28*J9 -> 48.308631 | K13: =1.28*K9 -> 53.314616 | L13: =1.28*L9 -> 59.611794 | M13: =1.28*M9 -> 63.10814 | N13: =1.28*N9 -> 67.011319 | O13: =1.28*O9 -> 71.181856 | P13: =1.28*P9 -> 71.181856 | Q13: =1.28*Q9 -> 71.181856 | ... AS13: =1.28*AS9 -> 71.181856
A14: LOW | B14: variable_coal | C14: fuel_price (R/GJ) | J14: 37.741118 | K14: 41.652043 | L14: 46.571714 | M14: 49.303235 | N14: 52.352593 | O14: 55.610825 | P14: =O14 -> 55.610825 | Q14: =P14 -> 55.610825 | R14: =Q14 -> 55.610825 | S14: =R14 -> 55.610825 | T14: =S14 -> 55.610825 | U14: =T14 -> 55.610825 | V14: =U14 -> 55.610825 | W14: =V14 -> 55.610825 | ... AS14: =AR14 -> 55.610825
A15: =A14 -> LOW | B15: variable_diesel | C15: fuel_price (R/GJ) | D15: 816 | E15: 816 | F15: 816 | G15: 816 | H15: 816 | I15: 816 | J15: =extendable_generators!J50 -> 388.87 | K15: =extendable_generators!K50 -> 372.94 | L15: =extendable_generators!L50 -> 356.79 | M15: =extendable_generators!M50 -> 341.89 | N15: =extendable_generators!N50 -> 326.08 | O15: =extendable_generators!O50 -> 311.33 | P15: =extendable_generators!P50 -> 313.23 | Q15: =extendable_generators!Q50 -> 312.72 | ... AS15: =extendable_generators!AS50 -> 345
A16: =A15 -> LOW | B16: low_group | C16: fuel_price (R/GJ) | J16: =0.74*J14 -> 27.928428 | K16: =0.74*K14 -> 30.822512 | L16: =0.74*L14 -> 34.463068 | M16: =0.74*M14 -> 36.484394 | N16: =0.74*N14 -> 38.740919 | O16: =0.74*O14 -> 41.15201 | P16: =0.74*P14 -> 41.15201 | Q16: =0.74*Q14 -> 41.15201 | ... AS16: =0.74*AS14 -> 41.15201
A17: =A16 -> LOW | B17: med_group | C17: fuel_price (R/GJ) | J17: =1.06*J14 -> 40.005585 | K17: =1.06*K14 -> 44.151166 | L17: =1.06*L14 -> 49.366017 | M17: =1.06*M14 -> 52.261429 | N17: =1.06*N14 -> 55.493749 | O17: =1.06*O14 -> 58.947474 | P17: =1.06*P14 -> 58.947474 | Q17: =1.06*Q14 -> 58.947474 | ... AS17: =1.06*AS14 -> 58.947474
A18: =A17 -> LOW | B18: high_group | C18: fuel_price (R/GJ) | J18: =1.28*J14 -> 48.308631 | K18: =1.28*K14 -> 53.314616 | L18: =1.28*L14 -> 59.611794 | M18: =1.28*M14 -> 63.10814 | N18: =1.28*N14 -> 67.011319 | O18: =1.28*O14 -> 71.181856 | P18: =1.28*P14 -> 71.181856 | Q18: =1.28*Q14 -> 71.181856 | ... AS18: =1.28*AS14 -> 71.181856
A19: CALC | B19: Komati | C19: ratio_vs_avg | J19: 1.28
A20: CALC | B20: Tutuka | C20: ratio_vs_avg | J20: 1.28
A21: CALC | B21: Matla | C21: ratio_vs_avg | J21: 1.28
A22: CALC | B22: Kusile | C22: ratio_vs_avg | J22: 1.28
A23: CALC | B23: Grootvlei | C23: ratio_vs_avg | J23: 1.28
A24: CALC | B24: Camden | C24: ratio_vs_avg | J24: 1.28
A25: CALC | B25: Kriel | C25: ratio_vs_avg | J25: 1.28
A26: CALC | B26: Hendrina | C26: ratio_vs_avg | J26: 1.06
A27: CALC | B27: Majuba | C27: ratio_vs_avg | J27: 1.06
A28: CALC | B28: Arnot | C28: ratio_vs_avg | J28: 1.06
A29: CALC | B29: Kendal | C29: ratio_vs_avg | J29: 1.06
A30: CALC | B30: Medupi | C30: ratio_vs_avg | J30: 0.74
... A33: CALC | B33: Lethabo | C33: ratio_vs_avg | J33: 0.74

Sheet extendable_generators
A1: scenario | B1: station_name | C1: parameter | D1: 2019 | E1: 2020 | F1: =E1+1 -> 2021 | G1: =F1+1 -> 2022 | H1: =G1+1 -> 2023 | I1: =H1+1 -> 2024 | J1: =I1+1 -> 2025 | K1: =J1+1 -> 2026 | L1: =K1+1 -> 2027 | M1: =L1+1 -> 2028 | ... AS1: =AR1+1 -> 2060
A2: IRP23 | B2: ocgt_diesel | C2: R/GJ | D2: 400.69668 | E2: 402.46947 | F2: 402.49144 | G2: 405.59713 | H2: 406.5107 | I2: 408.73353 | J2: 560 | K2: 560 | L2: 560 | M2: 560 | N2: 560 | O2: 560 | P2: 560 | Q2: 560 | R2: 560 | S2: 560 | T2: 560 | U2: 560 | V2: 560 | W2: 560 | X2: 560 | Y2: 560 | Z2: 560 | AA2: 560 | AB2: 560 | AC2: 560 | AD2: 560 | AE2: 560 | AF2: 560 | AG2: 560 | AH2: 560 | AI2: 560 | AJ2: 560 | AK2: 560 | AL2: 560 | AM2: 560 | AN2: 560 | AO2: 560 | AP2: 560 | AQ2: 560 | AR2: 560 | AS2: 560
A3: =A2 -> IRP23 | B3: ocgt_diesel_emg | C3: R/GJ | D3: 400.69668 | E3: 402.46947 | F3: 402.49144 | G3: 405.59713 | H3: 406.5107 | I3: 408.73353 | J3: 560 | K3: 560 | L3: 560 | M3: 560 | N3: 560 | O3: 560 | P3: 560 | Q3: 560 | R3: 560 | S3: 560 | T3: 560 | U3: 560 | V3: 560 | W3: 560 | X3: 560 | Y3: 560 | Z3: 560 | AA3: 560 | AB3: 560 | AC3: 560 | AD3: 560 | AE3: 560 | AF3: 560 | AG3: 560 | AH3: 560 | AI3: 560 | AJ3: 560 | AK3: 560 | AL3: 560 | AM3: 560 | AN3: 560 | AO3: 560 | AP3: 560 | AQ3: 560 | AR3: 560 | AS3: 560
A4: =A3 -> IRP23 | B4: ocgt_gas | C4: R/GJ | D4: 272 | E4: 272 | F4: 272 | G4: 272 | H4: 272 | I4: 272 | J4: 280 | K4: 280 | L4: 280 | M4: 280 | N4: 280 | O4: 280 | P4: 280 | Q4: 280 | R4: 280 | S4: 280 | T4: 280 | U4: 280 | V4: 280 | W4: 280 | X4: 280 | Y4: 280 | Z4: 280 | AA4: 280 | AB4: 280 | AC4: 280 | AD4: 280 | AE4: 280 | AF4: 280 | AG4: 280 | AH4: 280 | AI4: 280 | AJ4: 280 | AK4: 280 | AL4: 280 | AM4: 280 | AN4: 280 | AO4: 280 | AP4: 280 | AQ4: 280 | AR4: 280 | AS4: 280
A5: =A4 -> IRP23 | B5: ocgt_gas_h2_40 | C5: R/GJ | D5: 272 | E5: 272 | F5: 272 | G5: 272 | H5: 272 | I5: 272 | J5: =J4 -> 280 | K5: =K4 -> 280 | L5: =L4 -> 280 | M5: =M4 -> 280 | N5: =N4 -> 280 | O5: =O4 -> 280 | P5: =P4 -> 280 | Q5: =Q4 -> 280 | ... X5: =X4 -> 280 | Y5: =Y2 -> 560 | Z5: =Z2 -> 560 | AA5: =AA2 -> 560 | AB5: =AB2 -> 560 | AC5: =AC2 -> 560 | AD5: =AD2 -> 560 | AE5: =AE2 -> 560 | AF5: =AF2 -> 560 | ... AS5: =AS2 -> 560
A6: =A5 -> IRP23 | B6: ocgt_gas_h2_45 | C6: R/GJ | D6: 272 | E6: 272 | F6: 272 | G6: 272 | H6: 272 | I6: 272 | J6: =J4 -> 280 | K6: =K4 -> 280 | L6: =L4 -> 280 | M6: =M4 -> 280 | N6: =N4 -> 280 | O6: =O4 -> 280 | P6: =P4 -> 280 | Q6: =Q4 -> 280 | ... AC6: =AC4 -> 280 | AD6: =AD2 -> 560 | AE6: =AE2 -> 560 | AF6: =AF2 -> 560 | AG6: =AG2 -> 560 | AH6: =AH2 -> 560 | AI6: =AI2 -> 560 | AJ6: =AJ2 -> 560 | AK6: =AK2 -> 560 | ... AS6: =AS2 -> 560
A7: =A6 -> IRP23 | B7: ocgt_gas_h2_50 | C7: R/GJ | D7: 272 | E7: 272 | F7: 272 | G7: 272 | H7: 272 | I7: 272 | J7: =J4 -> 280 | K7: =K4 -> 280 | L7: =L4 -> 280 | M7: =M4 -> 280 | N7: =N4 -> 280 | O7: =O4 -> 280 | P7: =P4 -> 280 | Q7: =Q4 -> 280 | ... AH7: =AH4 -> 280 | AI7: =AI2 -> 560 | AJ7: =AJ2 -> 560 | AK7: =AK2 -> 560 | AL7: =AL2 -> 560 | AM7: =AM2 -> 560 | AN7: =AN2 -> 560 | AO7: =AO2 -> 560 | AP7: =AP2 -> 560 | ... AS7: =AS2 -> 560
A8: =A7 -> IRP23 | B8: ocgt_gas_h2_55 | C8: R/GJ | D8: 272 | E8: 272 | F8: 272 | G8: 272 | H8: 272 | I8: 272 | J8: =J6 -> 280 | K8: =K6 -> 280 | L8: =L6 -> 280 | M8: =M6 -> 280 | N8: =N6 -> 280 | O8: =O6 -> 280 | P8: =P6 -> 280 | Q8: =Q6 -> 280 | ... AC8: =AC6 -> 280 | AD8: =AD4 -> 280 | AE8: =AE4 -> 280 | AF8: =AF4 -> 280 | AG8: =AG4 -> 280 | AH8: =AH4 -> 280 | AI8: =AI4 -> 280 | AJ8: =AJ4 -> 280 | AK8: =AK4 -> 280 | ... AS8: =AS4 -> 280
A9: =A8 -> IRP23 | B9: ocgt_gas_h2_60 | C9: R/GJ | D9: 272 | E9: 272 | F9: 272 | G9: 272 | H9: 272 | I9: 272 | J9: =J6 -> 280 | K9: =K6 -> 280 | L9: =L6 -> 280 | M9: =M6 -> 280 | N9: =N6 -> 280 | O9: =O6 -> 280 | P9: =P6 -> 280 | Q9: =Q6 -> 280 | ... AH9: =AH6 -> 560 | AI9: =AI4 -> 280 | AJ9: =AJ4 -> 280 | AK9: =AK4 -> 280 | AL9: =AL4 -> 280 | AM9: =AM4 -> 280 | AN9: =AN4 -> 280 | AO9: =AO4 -> 280 | AP9: =AP4 -> 280 | ... AR9: =AR4 -> 280 | AS9: =AS2 -> 560
A10: =A7 -> IRP23 | B10: coal | C10: R/GJ | D10: 45.18 | E10: 45.18 | F10: 45.18 | G10: 45.18 | H10: 45.18 | I10: 45.18 | J10: 45.18 | K10: 45.18 | L10: 45.18 | M10: 45.18 | N10: 45.18 | O10: 45.18 | P10: 45.18 | Q10: 45.18 | R10: 45.18 | S10: 45.18 | T10: 45.18 | U10: 45.18 | V10: 45.18 | W10: 45.18 | X10: 45.18 | Y10: 45.18 | Z10: 45.18 | AA10: 45.18 | AB10: 45.18 | AC10: 45.18 | AD10: 45.18 | AE10: 45.18 | AF10: 45.18 | AG10: 45.18 | AH10: 45.18 | AI10: 45.18 | AJ10: =AI10 -> 45.18 | AK10: =AJ10 -> 45.18 | AL10: =AK10 -> 45.18 | AM10: =AL10 -> 45.18 | AN10: =AM10 -> 45.18 | AO10: =AN10 -> 45.18 | AP10: =AO10 -> 45.18 | AQ10: =AP10 -> 45.18 | ... AS10: =AR10 -> 45.18
A11: =A10 -> IRP23 | B11: nuclear | C11: R/GJ | D11: 18 | E11: 18 | F11: 18 | G11: 18 | H11: 18 | I11: 18 | J11: 18 | K11: 18 | L11: 18 | M11: 18 | N11: 18 | O11: 18 | P11: 18 | Q11: 18 | R11: 18 | S11: 18 | T11: 18 | U11: 18 | V11: 18 | W11: 18 | X11: 18 | Y11: 18 | Z11: 18 | AA11: 18 | AB11: 18 | AC11: 18 | AD11: 18 | AE11: 18 | AF11: 18 | AG11: 18 | AH11: 18 | AI11: 18 | AJ11: =AI11 -> 18 | AK11: =AJ11 -> 18 | AL11: =AK11 -> 18 | AM11: =AL11 -> 18 | AN11: =AM11 -> 18 | AO11: =AN11 -> 18 | AP11: =AO11 -> 18 | AQ11: =AP11 -> 18 | ... AS11: =AR11 -> 18
A12: =A11 -> IRP23 | B12: solar_csp | C12: R/GJ | D12: 0 | E12: 0 | F12: 0 | G12: 0 | H12: 0 | I12: 0 | J12: 0 | K12: 0 | L12: 0 | M12: 0 | N12: 0 | O12: 0 | P12: 0 | Q12: 0 | R12: 0 | S12: 0 | T12: 0 | U12: 0 | V12: 0 | W12: 0 | X12: 0 | Y12: 0 | Z12: 0 | AA12: 0 | AB12: 0 | AC12: 0 | AD12: 0 | AE12: 0 | AF12: 0 | AG12: 0 | AH12: 0 | AI12: 0 | AJ12: =AI12 -> 0 | AK12: =AJ12 -> 0 | AL12: =AK12 -> 0 | AM12: =AL12 -> 0 | AN12: =AM12 -> 0 | AO12: =AN12 -> 0 | AP12: =AO12 -> 0 | AQ12: =AP12 -> 0 | ... AS12: =AR12 -> 0
A13: =A12 -> IRP23 | B13: ccgt_steam | C13: R/GJ | D13: 0 | E13: 0 | F13: 0 | G13: 0 | H13: 0 | I13: 0 | J13: 0 | K13: 0 | L13: 0 | M13: 0 | N13: 0 | O13: 0 | P13: 0 | Q13: 0 | R13: 0 | S13: 0 | T13: 0 | U13: 0 | V13: 0 | W13: 0 | X13: 0 | Y13: 0 | Z13: 0 | AA13: 0 | AB13: 0 | AC13: 0 | AD13: 0 | AE13: 0 | AF13: 0 | AG13: 0 | AH13: 0 | AI13: 0 | AJ13: =AI13 -> 0 | AK13: =AJ13 -> 0 | AL13: =AK13 -> 0 | AM13: =AL13 -> 0 | AN13: =AM13 -> 0 | AO13: =AN13 -> 0 | AP13: =AO13 -> 0 | AQ13: =AP13 -> 0 | ... AS13: =AR13 -> 0
A14: ME_IRP23 | B14: ocgt_diesel | C14: R/GJ | D14: 400.69668 | E14: 402.46947 | F14: 402.49144 | G14: 405.59713 | H14: 406.5107 | I14: 408.73353 | J14: =816*1.06 -> 864.96 | K14: =816*1.06 -> 864.96 | L14: =816*1.06 -> 864.96 | M14: =816*1.06 -> 864.96 | N14: =816*1.06 -> 864.96 | O14: =816*1.06 -> 864.96 | P14: =816*1.06 -> 864.96 | Q14: =816*1.06 -> 864.96 | ... AS14: =816*1.06 -> 864.96
A15: =A14 -> ME_IRP23 | B15: ocgt_diesel_emg | C15: R/GJ | D15: 400.69668 | E15: 402.46947 | F15: 402.49144 | G15: 405.59713 | H15: 406.5107 | I15: 408.73353 | J15: =816*1.06 -> 864.96 | K15: =816*1.06 -> 864.96 | L15: =816*1.06 -> 864.96 | M15: =816*1.06 -> 864.96 | N15: =816*1.06 -> 864.96 | O15: =816*1.06 -> 864.96 | P15: =816*1.06 -> 864.96 | Q15: =816*1.06 -> 864.96 | ... AS15: =816*1.06 -> 864.96
A16: =A15 -> ME_IRP23 | B16: ocgt_gas | C16: R/GJ | D16: 272 | E16: 272 | F16: 272 | G16: 272 | H16: 272 | I16: 272 | J16: =272*1.06 -> 288.32 | K16: =272*1.06 -> 288.32 | L16: =272*1.06 -> 288.32 | M16: =272*1.06 -> 288.32 | N16: =272*1.06 -> 288.32 | O16: =272*1.06 -> 288.32 | P16: =272*1.06 -> 288.32 | Q16: =272*1.06 -> 288.32 | ... AS16: =272*1.06 -> 288.32
A17: =A16 -> ME_IRP23 | B17: ocgt_gas_h2_40 | C17: R/GJ | D17: 272 | E17: 272 | F17: 272 | G17: 272 | H17: 272 | I17: 272 | J17: =J16 -> 288.32 | K17: =K16 -> 288.32 | L17: =L16 -> 288.32 | M17: =M16 -> 288.32 | N17: =N16 -> 288.32 | O17: =O16 -> 288.32 | P17: =P16 -> 288.32 | Q17: =Q16 -> 288.32 | ... X17: =X16 -> 288.32 | Y17: =Y14 -> 864.96 | Z17: =Z14 -> 864.96 | AA17: =AA14 -> 864.96 | AB17: =AB14 -> 864.96 | AC17: =AC14 -> 864.96 | AD17: =AD14 -> 864.96 | AE17: =AE14 -> 864.96 | AF17: =AF14 -> 864.96 | ... AS17: =AS14 -> 864.96
A18: =A17 -> ME_IRP23 | B18: ocgt_gas_h2_45 | C18: R/GJ | D18: 272 | E18: 272 | F18: 272 | G18: 272 | H18: 272 | I18: 272 | J18: =J16 -> 288.32 | K18: =K16 -> 288.32 | L18: =L16 -> 288.32 | M18: =M16 -> 288.32 | N18: =N16 -> 288.32 | O18: =O16 -> 288.32 | P18: =P16 -> 288.32 | Q18: =Q16 -> 288.32 | ... AC18: =AC16 -> 288.32 | AD18: =AD14 -> 864.96 | AE18: =AE14 -> 864.96 | AF18: =AF14 -> 864.96 | AG18: =AG14 -> 864.96 | AH18: =AH14 -> 864.96 | AI18: =AI14 -> 864.96 | AJ18: =AJ14 -> 864.96 | AK18: =AK14 -> 864.96 | ... AS18: =AS14 -> 864.96
A19: =A18 -> ME_IRP23 | B19: ocgt_gas_h2_50 | C19: R/GJ | D19: 272 | E19: 272 | F19: 272 | G19: 272 | H19: 272 | I19: 272 | J19: =J16 -> 288.32 | K19: =K16 -> 288.32 | L19: =L16 -> 288.32 | M19: =M16 -> 288.32 | N19: =N16 -> 288.32 | O19: =O16 -> 288.32 | P19: =P16 -> 288.32 | Q19: =Q16 -> 288.32 | ... AH19: =AH16 -> 288.32 | AI19: =AI14 -> 864.96 | AJ19: =AJ14 -> 864.96 | AK19: =AK14 -> 864.96 | AL19: =AL14 -> 864.96 | AM19: =AM14 -> 864.96 | AN19: =AN14 -> 864.96 | AO19: =AO14 -> 864.96 | AP19: =AP14 -> 864.96 | ... AS19: =AS14 -> 864.96
A20: =A19 -> ME_IRP23 | B20: ocgt_gas_h2_55 | C20: R/GJ | D20: 272 | E20: 272 | F20: 272 | G20: 272 | H20: 272 | I20: 272 | J20: =J18 -> 288.32 | K20: =K18 -> 288.32 | L20: =L18 -> 288.32 | M20: =M18 -> 288.32 | N20: =N18 -> 288.32 | O20: =O18 -> 288.32 | P20: =P18 -> 288.32 | Q20: =Q18 -> 288.32 | ... AB20: =AB18 -> 288.32 | AC20: =AC16 -> 288.32 | AD20: =AD16 -> 288.32 | AE20: =AE16 -> 288.32 | AF20: =AF16 -> 288.32 | AG20: =AG16 -> 288.32 | AH20: =AH16 -> 288.32 | AI20: =AI16 -> 288.32 | AJ20: =AJ16 -> 288.32 | ... AM20: =AM16 -> 288.32 | AN20: =AN18 -> 864.96 | AO20: =AO18 -> 864.96 | AP20: =AP18 -> 864.96 | AQ20: =AQ18 -> 864.96 | AR20: =AR18 -> 864.96 | AS20: =AS18 -> 864.96
A21: =A20 -> ME_IRP23 | B21: ocgt_gas_h2_60 | C21: R/GJ | D21: 272 | E21: 272 | F21: 272 | G21: 272 | H21: 272 | I21: 272 | J21: =J18 -> 288.32 | K21: =K18 -> 288.32 | L21: =L18 -> 288.32 | M21: =M18 -> 288.32 | N21: =N18 -> 288.32 | O21: =O18 -> 288.32 | P21: =P18 -> 288.32 | Q21: =Q18 -> 288.32 | ... AB21: =AB18 -> 288.32 | AC21: =AC16 -> 288.32 | AD21: =AD16 -> 288.32 | AE21: =AE16 -> 288.32 | AF21: =AF16 -> 288.32 | AG21: =AG16 -> 288.32 | AH21: =AH16 -> 288.32 | AI21: =AI16 -> 288.32 | AJ21: =AJ16 -> 288.32 | ... AR21: =AR16 -> 288.32 | AS21: =AS14 -> 864.96
A22: =A21 -> ME_IRP23 | B22: coal | C22: R/GJ | D22: 45.18 | E22: 45.18 | F22: 45.18 | G22: 45.18 | H22: 45.18 | I22: 45.18 | J22: =1.06*45.18 -> 47.8908 | K22: =1.06*45.18 -> 47.8908 | L22: =1.06*45.18 -> 47.8908 | M22: =1.06*45.18 -> 47.8908 | N22: =1.06*45.18 -> 47.8908 | O22: =1.06*45.18 -> 47.8908 | P22: =1.06*45.18 -> 47.8908 | Q22: =1.06*45.18 -> 47.8908 | ... AS22: =1.06*45.18 -> 47.8908
A23: =A22 -> ME_IRP23 | B23: nuclear | C23: R/GJ | D23: 18 | E23: 18 | F23: 18 | G23: 18 | H23: 18 | I23: 18 | J23: =1.06*18 -> 19.08 | K23: =1.06*18 -> 19.08 | L23: =1.06*18 -> 19.08 | M23: =1.06*18 -> 19.08 | N23: =1.06*18 -> 19.08 | O23: =1.06*18 -> 19.08 | P23: =1.06*18 -> 19.08 | Q23: =1.06*18 -> 19.08 | ... AS23: =1.06*18 -> 19.08
A24: =A23 -> ME_IRP23 | B24: solar_csp | C24: R/GJ | D24: 0 | E24: 0 | F24: 0 | G24: 0 | H24: 0 | I24: 0 | J24: 0 | K24: 0 | L24: 0 | M24: 0 | N24: 0 | O24: 0 | P24: 0 | Q24: 0 | R24: 0 | S24: 0 | T24: 0 | U24: 0 | V24: 0 | W24: 0 | X24: 0 | Y24: 0 | Z24: 0 | AA24: 0 | AB24: 0 | AC24: 0 | AD24: 0 | AE24: 0 | AF24: 0 | AG24: 0 | AH24: 0 | AI24: 0 | AJ24: =AI24 -> 0 | AK24: =AJ24 -> 0 | AL24: =AK24 -> 0 | AM24: =AL24 -> 0 | AN24: =AM24 -> 0 | AO24: =AN24 -> 0 | AP24: =AO24 -> 0 | AQ24: =AP24 -> 0 | ... AS24: =AR24 -> 0
A25: =A24 -> ME_IRP23 | B25: ccgt_steam | C25: R/GJ | D25: 0 | E25: 0 | F25: 0 | G25: 0 | H25: 0 | I25: 0 | J25: 0 | K25: 0 | L25: 0 | M25: 0 | N25: 0 | O25: 0 | P25: 0 | Q25: 0 | R25: 0 | S25: 0 | T25: 0 | U25: 0 | V25: 0 | W25: 0 | X25: 0 | Y25: 0 | Z25: 0 | AA25: 0 | AB25: 0 | AC25: 0 | AD25: 0 | AE25: 0 | AF25: 0 | AG25: 0 | AH25: 0 | AI25: 0 | AJ25: =AI25 -> 0 | AK25: =AJ25 -> 0 | AL25: =AK25 -> 0 | AM25: =AL25 -> 0 | AN25: =AM25 -> 0 | AO25: =AN25 -> 0 | AP25: =AO25 -> 0 | AQ25: =AP25 -> 0 | ... AS25: =AR25 -> 0
A26: HIGH | B26: ocgt_diesel | C26: R/GJ | D26: 667.51684 | E26: 669.91818 | F26: 670.59782 | G26: 676.03509 | H26: 680.63895 | I26: 685.52927 | J26: 388.87 | K26: 404.1 | L26: 418.4 | M26: 432.19 | N26: 446.49 | O26: 462.62 | P26: 468.14 | Q26: 468.5 | R26: 473.81 | S26: 479.77 | T26: 483.6 | U26: 487.23 | V26: 492.08 | W26: 497.73 | X26: 504.74 | Y26: 509.26 | Z26: 505.89 | AA26: 514.87 | AB26: 519.71 | AC26: 523.98 | AD26: 526.21 | AE26: 525.22 | AF26: 532.99 | AG26: 536.15 | AH26: 540.24 | AI26: 543.9 | AJ26: 544 | AK26: 544 | AL26: 544 | AM26: 544 | AN26: 544 | AO26: 544 | AP26: 544 | AQ26: 544 | AR26: 544 | AS26: 544
A27: =A26 -> HIGH | B27: ocgt_diesel_emg | C27: R/GJ | D27: 667.51684 | E27: 669.91818 | F27: 670.59782 | G27: 676.03509 | H27: 680.63895 | I27: 685.52927 | J27: 388.87 | K27: 404.1 | L27: 418.4 | M27: 432.19 | N27: 446.49 | O27: 462.62 | P27: 468.14 | Q27: 468.5 | R27: 473.81 | S27: 479.77 | T27: 483.6 | U27: 487.23 | V27: 492.08 | W27: 497.73 | X27: 504.74 | Y27: 509.26 | Z27: 505.89 | AA27: 514.87 | AB27: 519.71 | AC27: 523.98 | AD27: 526.21 | AE27: 525.22 | AF27: 532.99 | AG27: 536.15 | AH27: 540.24 | AI27: 543.9 | AJ27: 544 | AK27: 544 | AL27: 544 | AM27: 544 | AN27: 544 | AO27: 544 | AP27: 544 | AQ27: 544 | AR27: 544 | AS27: 544
A28: =A27 -> HIGH | B28: ocgt_gas | C28: R/GJ | D28: 184 | E28: 184 | F28: 184 | G28: 184 | H28: 184 | I28: 184 | J28: 216.16 | K28: 225.89 | L28: 235.02 | M28: 243.83 | N28: 252.96 | O28: 263.26 | P28: 266.78 | Q28: 267.01 | R28: 270.4 | S28: 274.21 | T28: 276.66 | U28: 278.98 | V28: 282.07 | W28: 285.68 | X28: 290.16 | Y28: 293.04 | Z28: 290.9 | AA28: 296.63 | AB28: 299.72 | AC28: 302.45 | AD28: 303.87 | AE28: 303.24 | AF28: 308.2 | AG28: 310.22 | AH28: 312.83 | AI28: 315.17 | AJ28: 315 | AK28: 315 | AL28: 315 | AM28: 315 | AN28: 315 | AO28: 315 | AP28: 315 | AQ28: 315 | AR28: 315 | AS28: 315
A29: =A28 -> HIGH | B29: ocgt_gas_h2_40 | C29: R/GJ | D29: 184 | E29: 184 | F29: 184 | G29: 184 | H29: 184 | I29: 184 | J29: =J28 -> 216.16 | K29: =K28 -> 225.89 | L29: =L28 -> 235.02 | M29: =M28 -> 243.83 | N29: =N28 -> 252.96 | O29: =O28 -> 263.26 | P29: =P28 -> 266.78 | Q29: =Q28 -> 267.01 | ... X29: =X28 -> 290.16 | Y29: 509 | Z29: 506 | AA29: 515 | AB29: 520 | AC29: 524 | AD29: 526 | AE29: 525 | AF29: 533 | AG29: 536 | AH29: 540 | AI29: 544 | AJ29: 544 | AK29: 544 | AL29: 544 | AM29: 544 | AN29: 544 | AO29: 544 | AP29: 544 | AQ29: 544 | AR29: 544 | AS29: 544
A30: =A29 -> HIGH | B30: ocgt_gas_h2_45 | C30: R/GJ | D30: 184 | E30: 184 | F30: 184 | G30: 184 | H30: 184 | I30: 184 | J30: =J28 -> 216.16 | K30: =K28 -> 225.89 | L30: =L28 -> 235.02 | M30: =M28 -> 243.83 | N30: =N28 -> 252.96 | O30: =O28 -> 263.26 | P30: =P28 -> 266.78 | Q30: =Q28 -> 267.01 | ... AC30: =AC28 -> 302.45 | AD30: 526 | AE30: 525 | AF30: 533 | AG30: 536 | AH30: 540 | AI30: 544 | AJ30: 544 | AK30: 544 | AL30: 544 | AM30: 544 | AN30: 544 | AO30: 544 | AP30: 544 | AQ30: 544 | AR30: 544 | AS30: 544
A31: =A30 -> HIGH | B31: ocgt_gas_h2_50 | C31: R/GJ | D31: 184 | E31: 184 | F31: 184 | G31: 184 | H31: 184 | I31: 184 | J31: =J28 -> 216.16 | K31: =K28 -> 225.89 | L31: =L28 -> 235.02 | M31: =M28 -> 243.83 | N31: =N28 -> 252.96 | O31: =O28 -> 263.26 | P31: =P28 -> 266.78 | Q31: =Q28 -> 267.01 | ... AH31: =AH28 -> 312.83 | AI31: 544 | AJ31: 544 | AK31: 544 | AL31: 544 | AM31: 544 | AN31: 544 | AO31: 544 | AP31: 544 | AQ31: 544 | AR31: 544 | AS31: 544
A32: =A31 -> HIGH | B32: ocgt_gas_h2_55 | C32: R/GJ | D32: 184 | E32: 184 | F32: 184 | G32: 184 | H32: 184 | I32: 184 | J32: =J28 -> 216.16 | K32: =K28 -> 225.89 | L32: =L28 -> 235.02 | M32: =M28 -> 243.83 | N32: =N28 -> 252.96 | O32: =O28 -> 263.26 | P32: =P28 -> 266.78 | Q32: =Q28 -> 267.01 | ... AM32: =AM28 -> 315 | AN32: 544 | AO32: 544 | AP32: 544 | AQ32: 544 | AR32: 544 | AS32: 544
A33: =A32 -> HIGH | B33: ocgt_gas_h2_60 | C33: R/GJ | D33: 184 | E33: 184 | F33: 184 | G33: 184 | H33: 184 | I33: 184 | J33: =J28 -> 216.16 | K33: =K28 -> 225.89 | L33: =L28 -> 235.02 | M33: =M28 -> 243.83 | N33: =N28 -> 252.96 | O33: =O28 -> 263.26 | P33: =P28 -> 266.78 | Q33: =Q28 -> 267.01 | ... AR33: =AR28 -> 315 | AS33: 544
A34: =A33 -> HIGH | B34: coal | C34: R/GJ | D34: 45.18 | E34: 45.18 | F34: 45.18 | G34: 45.18 | H34: 45.18 | I34: 45.18 | J34: 45 | K34: 45 | L34: 45 | M34: 45 | N34: 45 | O34: 45 | P34: 45 | Q34: 45 | R34: 45 | S34: 45 | T34: 45 | U34: 45 | V34: 45 | W34: 45 | X34: 45 | Y34: 45 | Z34: 45 | AA34: 45 | AB34: 45 | AC34: 45 | AD34: 45 | AE34: 45 | AF34: 45 | AG34: 45 | AH34: 45 | AI34: 45 | AJ34: 45 | AK34: 45 | AL34: 45 | AM34: 45 | AN34: 45 | AO34: 45 | AP34: 45 | AQ34: 45 | AR34: 45 | AS34: 45
A35: =A34 -> HIGH | B35: nuclear | C35: R/GJ | D35: 18 | E35: 18 | F35: 18 | G35: 18 | H35: 18 | I35: 18 | J35: 18 | K35: 18 | L35: 18 | M35: 18 | N35: 18 | O35: 18 | P35: 18 | Q35: 18 | R35: 18 | S35: 18 | T35: 18 | U35: 18 | V35: 18 | W35: 18 | X35: 18 | Y35: 18 | Z35: 18 | AA35: 18 | AB35: 18 | AC35: 18 | AD35: 18 | AE35: 18 | AF35: 18 | AG35: 18 | AH35: 18 | AI35: 18 | AJ35: 18 | AK35: 18 | AL35: 18 | AM35: 18 | AN35: 18 | AO35: 18 | AP35: 18 | AQ35: 18 | AR35: 18 | AS35: 18
A36: =A35 -> HIGH | B36: solar_csp | C36: R/GJ | D36: 0 | E36: 0 | F36: 0 | G36: 0 | H36: 0 | I36: 0 | J36: 0 | K36: 0 | L36: 0 | M36: 0 | N36: 0 | O36: 0 | P36: 0 | Q36: 0 | R36: 0 | S36: 0 | T36: 0 | U36: 0 | V36: 0 | W36: 0 | X36: 0 | Y36: 0 | Z36: 0 | AA36: 0 | AB36: 0 | AC36: 0 | AD36: 0 | AE36: 0 | AF36: 0 | AG36: 0 | AH36: 0 | AI36: 0 | AJ36: 0 | AK36: 0 | AL36: 0 | AM36: 0 | AN36: 0 | AO36: 0 | AP36: 0 | AQ36: 0 | AR36: 0 | AS36: 0
A37: =A36 -> HIGH | B37: ccgt_steam | C37: R/GJ | D37: 0 | E37: 0 | F37: 0 | G37: 0 | H37: 0 | I37: 0 | J37: 0 | K37: 0 | L37: 0 | M37: 0 | N37: 0 | O37: 0 | P37: 0 | Q37: 0 | R37: 0 | S37: 0 | T37: 0 | U37: 0 | V37: 0 | W37: 0 | X37: 0 | Y37: 0 | Z37: 0 | AA37: 0 | AB37: 0 | AC37: 0 | AD37: 0 | AE37: 0 | AF37: 0 | AG37: 0 | AH37: 0 | AI37: 0 | AJ37: 0 | AK37: 0 | AL37: 0 | AM37: 0 | AN37: 0 | AO37: 0 | AP37: 0 | AQ37: 0 | AR37: 0 | AS37: 0
A38: BASE | B38: ocgt_diesel | C38: R/GJ | D38: 506.07771 | E38: 509.25357 | F38: 510.86624 | G38: 513.0464 | H38: 515.29938 | I38: 517.9345 | J38: 388.87 | K38: 388.6 | L38: 386.77 | M38: 384.37 | N38: 382.13 | O38: 381.53 | P38: 383.6 | Q38: 381.66 | R38: 386.9 | S38: 389.56 | T38: 390.76 | U38: 391.8 | V38: 394.01 | W38: 395.09 | X38: 397.38 | Y38: 399.25 | Z38: 400.63 | AA38: 400.03 | AB38: 404.73 | AC38: 404.67 | AD38: 406.38 | AE38: 408.01 | AF38: 417.44 | AG38: 419.63 | AH38: 422.8 | AI38: 424.07 | AJ38: 424 | AK38: 424 | AL38: 424 | AM38: 424 | AN38: 424 | AO38: 424 | AP38: 424 | AQ38: 424 | AR38: 424 | AS38: 424
A39: =A38 -> BASE | B39: ocgt_diesel_emg | C39: R/GJ | D39: 506.07771 | E39: 509.25357 | F39: 510.86624 | G39: 513.0464 | H39: 515.29938 | I39: 517.9345 | J39: =J38 -> 388.87 | K39: =K38 -> 388.6 | L39: =L38 -> 386.77 | M39: =M38 -> 384.37 | N39: =N38 -> 382.13 | O39: =O38 -> 381.53 | P39: =P38 -> 383.6 | Q39: =Q38 -> 381.66 | ... AS39: =AS38 -> 424
A40: =A39 -> BASE | B40: ocgt_gas | C40: R/GJ | D40: 272 | E40: 272 | F40: 272 | G40: 272 | H40: 272 | I40: 272 | J40: 216.16 | K40: 215.99 | L40: 214.82 | M40: 213.29 | N40: 211.85 | O40: 211.47 | P40: 212.8 | Q40: 211.55 | R40: 214.9 | S40: 216.6 | T40: 217.37 | U40: 218.03 | V40: 219.44 | W40: 220.13 | X40: 221.6 | Y40: 222.79 | Z40: 223.67 | AA40: 223.29 | AB40: 226.29 | AC40: 226.25 | AD40: 227.34 | AE40: 228.38 | AF40: 234.4 | AG40: 235.81 | AH40: 237.83 | AI40: 238.64 | AJ40: =AI40 -> 238.64 | AK40: =AJ40 -> 238.64 | AL40: =AK40 -> 238.64 | AM40: =AL40 -> 238.64 | AN40: =AM40 -> 238.64 | AO40: =AN40 -> 238.64 | AP40: =AO40 -> 238.64 | AQ40: =AP40 -> 238.64 | ... AS40: =AR40 -> 238.64
...

Sheet green_NH3
A1: 2020.0467 | B1: 714.28399 | C1: 1394.413 | D1: $/t | E1: CV | F1: 0.0185 | G1: GJ/kg
A2: 2029.9994 | B2: 473.07826 | C2: 948.23786 | D2: $/t | F2: 18.7 | G2: ZAR:USD
A3: 2050.0066 | B3: 313.65872 | C3: 611.79273 | D3: $/t
A6: 2020 | B6: =B1/1000 -> 0.71428399 | C6: =C1/1000 -> 1.394413 | D6: $/kg | E6: =B6/$F$1*$F$2 -> 722.00598 | F6: =C6/$F$1*$F$2 -> 1409.4877 | G6: R/GJ | H6: =E6/0.278 -> 2597.1438 | I6: =H6/0.5 -> 5194.2877
A7: 2030 | B7: =B2/1000 -> 0.47307826 | C7: =C2/1000 -> 0.94823786 | D7: $/kg | E7: =B7/$F$1*$F$2 -> 478.19262 | F7: =C7/$F$1*$F$2 -> 958.48908 | G7: R/GJ | H7: =E7/0.278 -> 1720.1173 | I7: =H7/0.5 -> 3440.2347
A8: 2040 | B8: =0.5*B7+0.5*B9 -> 0.39336849 | C8: =0.5*C7+0.5*C9 -> 0.7800153 | D8: $/kg | E8: =B8/$F$1*$F$2 -> 397.62112 | F8: =C8/$F$1*$F$2 -> 788.4479 | G8: R/GJ | H8: =E8/0.278 -> 1430.2918 | I8: =H8/0.5 -> 2860.5836
A9: 2050 | B9: =B3/1000 -> 0.31365872 | C9: =C3/1000 -> 0.61179273 | D9: $/kg | E9: =B9/$F$1*$F$2 -> 317.04962 | F9: =C9/$F$1*$F$2 -> 618.40671 | G9: R/GJ | H9: =E9/0.278 -> 1140.4663 | I9: =H9/0.5 -> 2280.9325
A10: 2060
A12: https://www.irena.org/-/media/Files/IRENA/Agency/Publication/2022/May/IRENA_Innovation_Outlook_Ammonia_2022.pdf
P16: https://ora.ox.ac.uk/objects/uuid:475ce7d3-b6b8-42f6-8cb1-b33f56026689/files/r2801pg46c
K23: =600/0.278 -> 2158.2734 | L23: =K23/0.5 -> 4316.5468
H38: https://www.sciencedirect.com/science/article/abs/pii/S0306261920314549?via%3Dihub
G41: https://pubs.acs.org/doi/pdf/10.1021/acsenergylett.2c01615
A89: https://pubs.rsc.org/zh-tw/content/articlepdf/2024/ee/d3ee02951d

Sheet carbon_tax
A1: scenario | B1: units | C1: 2024 | D1: 2025 | E1: =D1+1 -> 2026 | F1: =E1+1 -> 2027 | G1: =F1+1 -> 2028 | H1: =G1+1 -> 2029 | I1: =H1+1 -> 2030 | J1: =I1+1 -> 2031 | K1: =J1+1 -> 2032 | L1: =K1+1 -> 2033 | ... AM1: =AL1+1 -> 2060
A2: none | B2: R/tCO2e | C2: 0 | D2: =C2 -> 0 | E2: =D2 -> 0 | F2: =E2 -> 0 | G2: =F2 -> 0 | H2: =G2 -> 0 | I2: =H2 -> 0 | J2: =I2 -> 0 | K2: =J2 -> 0 | ... AM2: =AL2 -> 0
A3: IRP23 | B3: R/tCO2e | C3: 0 | D3: 0 | E3: 308 | F3: 347 | G3: 385 | H3: 424 | I3: 462 | J3: =($S$3-$I$3)/10+I3 -> 507.95 | K3: =($S$3-$I$3)/10+J3 -> 553.9 | L3: =($S$3-$I$3)/10+K3 -> 599.85 | M3: =($S$3-$I$3)/10+L3 -> 645.8 | N3: =($S$3-$I$3)/10+M3 -> 691.75 | O3: =($S$3-$I$3)/10+N3 -> 737.7 | P3: =($S$3-$I$3)/10+O3 -> 783.65 | Q3: =($S$3-$I$3)/10+P3 -> 829.6 | R3: =($S$3-$I$3)/10+Q3 -> 875.55 | S3: =50*18.43 -> 921.5 | T3: =($AC$3-$S$3)/10+S3 -> 1013.65 | U3: =($AC$3-$S$3)/10+T3 -> 1105.8 | V3: =($AC$3-$S$3)/10+U3 -> 1197.95 | W3: =($AC$3-$S$3)/10+V3 -> 1290.1 | X3: =($AC$3-$S$3)/10+W3 -> 1382.25 | Y3: =($AC$3-$S$3)/10+X3 -> 1474.4 | Z3: =($AC$3-$S$3)/10+Y3 -> 1566.55 | AA3: =($AC$3-$S$3)/10+Z3 -> 1658.7 | AB3: =($AC$3-$S$3)/10+AA3 -> 1750.85 | AC3: =100*18.43 -> 1843 | AD3: =+($AC$3-$S$3)/10+AC3 -> 1935.15 | AE3: =+($AC$3-$S$3)/10+AD3 -> 2027.3 | AF3: =+($AC$3-$S$3)/10+AE3 -> 2119.45 | AG3: =+($AC$3-$S$3)/10+AF3 -> 2211.6 | AH3: =+($AC$3-$S$3)/10+AG3 -> 2303.75 | AI3: =+($AC$3-$S$3)/10+AH3 -> 2395.9 | AJ3: =+($AC$3-$S$3)/10+AI3 -> 2488.05 | AK3: =+($AC$3-$S$3)/10+AJ3 -> 2580.2 | ... AM3: =+($AC$3-$S$3)/10+AL3 -> 2764.5
A4: LOW | B4: R/tCO2e | C4: 30 | D4: 30 | E4: 30 | F4: 30 | G4: 30 | H4: 30 | I4: 30 | J4: 127.05 | K4: 138.6 | L4: 150.15 | M4: 161.7 | N4: 173.25 | O4: 230.08 | P4: 292.57 | Q4: 360.72 | R4: 434.53 | S4: 514 | T4: 599.13 | U4: 689.92 | V4: 786.37 | W4: 888.48 | X4: 996.25 | Y4: 1109.68 | Z4: 1183.26 | AA4: 1256.84 | AB4: 1330.42 | AC4: 1404 | AD4: 1477.58 | AE4: 1551.16 | AF4: 1624.74 | AG4: 1698.32 | AH4: 1771.9 | AI4: 1845.48 | AJ4: 1919.06 | AK4: 1992.64 | AL4: 2066.22 | AM4: 2139.8
A5: BASE | B5: R/tCO2e | C5: 30 | D5: 30 | E5: 30 | F5: 30 | G5: 30 | H5: 30 | I5: 30 | J5: 242.55 | K5: 254.1 | L5: 265.65 | M5: 277.2 | N5: 288.75 | O5: 373.88 | P5: 464.67 | Q5: 561.12 | R5: 663.23 | S5: 771 | T5: 884.43 | U5: 1003.52 | V5: 1128.27 | W5: 1258.68 | X5: 1394.75 | Y5: 1536.48 | Z5: 1638.36 | AA5: 1740.24 | AB5: 1842.12 | AC5: 1944 | AD5: 2045.88 | AE5: 2147.76 | AF5: 2249.64 | AG5: 2351.52 | AH5: 2453.4 | AI5: 2555.28 | AJ5: 2657.16 | AK5: 2759.04 | AL5: 2860.92 | AM5: 2962.8
A6: HIGH | B6: R/tCO2e | C6: 30 | D6: 30 | E6: 30 | F6: 30 | G6: 30 | H6: 30 | I6: 30 | J6: 462 | K6: 462 | L6: 462 | M6: 462 | N6: 462 | O6: 575.2 | P6: 688.4 | Q6: 801.6 | R6: 914.8 | S6: 1028 | T6: 1141.2 | U6: 1254.4 | V6: 1367.6 | W6: 1480.8 | X6: 1594 | Y6: 1707.2 | Z6: 1820.4 | AA6: 1933.6 | AB6: 2046.8 | AC6: 2160 | AD6: 2273.2 | AE6: 2386.4 | AF6: 2499.6 | AG6: 2612.8 | AH6: 2726 | AI6: 2839.2 | AJ6: 2952.4 | AK6: 3065.6 | AL6: 3178.8 | AM6: 3292
A8: emissions
